Workbook

Sheet Preencher pelo celular
A1: Data | B1: Refeição | C1: Glicemia antes (mg/dL) | D1: Insulina (unidades) | E1: O que comeu e bebeu | F1: Glicemia 2h depois (mg/dL) | G1: Observações
A2: ='Como usar'!$B$4+INT((ROW()-2)/6) -> 46290 | B2: Café da manhã
A3: ='Como usar'!$B$4+INT((ROW()-2)/6) -> 46290 | B3: Lanche
A4: ='Como usar'!$B$4+INT((ROW()-2)/6) -> 46290 | B4: Almoço
A5: ='Como usar'!$B$4+INT((ROW()-2)/6) -> 46290 | B5: Café da tarde
A6: ='Como usar'!$B$4+INT((ROW()-2)/6) -> 46290 | B6: Janta
A7: ='Como usar'!$B$4+INT((ROW()-2)/6) -> 46290 | B7: Ceia
A8: ='Como usar'!$B$4+INT((ROW()-2)/6) -> 46291 | B8: Café da manhã
A9: ='Como usar'!$B$4+INT((ROW()-2)/6) -> 46291 | B9: Lanche
A10: ='Como usar'!$B$4+INT((ROW()-2)/6) -> 46291 | B10: Almoço
A11: ='Como usar'!$B$4+INT((ROW()-2)/6) -> 46291 | B11: Café da tarde
A12: ='Como usar'!$B$4+INT((ROW()-2)/6) -> 46291 | B12: Janta
A13: ='Como usar'!$B$4+INT((ROW()-2)/6) -> 46291 | B13: Ceia
... A541: ='Como usar'!$B$4+INT((ROW()-2)/6) -> 46379 | B541: Ceia

Sheet Histórico por dia
A1: HISTÓRICO POR DIA - GLICEMIA (mg/dL) E INSULINA (unidades)
A2: Data | B2: Café da manhã | E2: Lanche | H2: Almoço | K2: Café da tarde | N2: Janta | Q2: Ceia | T2: Média antes | U2: Média 2h depois | V2: Insulina total
B3: Antes | C3: Insul. | D3: 2h dep. | E3: Antes | F3: Insul. | G3: 2h dep. | H3: Antes | I3: Insul. | J3: 2h dep. | K3: Antes | L3: Insul. | M3: 2h dep. | N3: Antes | O3: Insul. | P3: 2h dep. | Q3: Antes | R3: Insul. | S3: 2h dep.
A4: ='Preencher pelo celular'!A2 -> 46290 | B4: =IF('Preencher pelo celular'!C2="","",'Preencher pelo celular'!C2) | C4: =IF('Preencher pelo celular'!D2="","",'Preencher pelo celular'!D2) | D4: =IF('Preencher pelo celular'!F2="","",'Preencher pelo celular'!F2) | E4: =IF('Preencher pelo celular'!C3="","",'Preencher pelo celular'!C3) | F4: =IF('Preencher pelo celular'!D3="","",'Preencher pelo celular'!D3) | G4: =IF('Preencher pelo celular'!F3="","",'Preencher pelo celular'!F3) | H4: =IF('Preencher pelo celular'!C4="","",'Preencher pelo celular'!C4) | I4: =IF('Preencher pelo celular'!D4="","",'Preencher pelo celular'!D4) | J4: =IF('Preencher pelo celular'!F4="","",'Preencher pelo celular'!F4) | K4: =IF('Preencher pelo celular'!C5="","",'Preencher pelo celular'!C5) | L4: =IF('Preencher pelo celular'!D5="","",'Preencher pelo celular'!D5) | M4: =IF('Preencher pelo celular'!F5="","",'Preencher pelo celular'!F5) | N4: =IF('Preencher pelo celular'!C6="","",'Preencher pelo celular'!C6) | O4: =IF('Preencher pelo celular'!D6="","",'Preencher pelo celular'!D6) | P4: =IF('Preencher pelo celular'!F6="","",'Preencher pelo celular'!F6) | Q4: =IF('Preencher pelo celular'!C7="","",'Preencher pelo celular'!C7) | R4: =IF('Preencher pelo celular'!D7="","",'Preencher pelo celular'!D7) | S4: =IF('Preencher pelo celular'!F7="","",'Preencher pelo celular'!F7) | T4: =IF(COUNT(B4,E4,H4,K4,N4,Q4)=0,"",AVERAGE(B4,E4,H4,K4,N4,Q4)) | U4: =IF(COUNT(D4,G4,J4,M4,P4,S4)=0,"",AVERAGE(D4,G4,J4,M4,P4,S4)) | V4: =IF(COUNT(C4,F4,I4,L4,O4,R4)=0,"",SUM(C4,F4,I4,L4,O4,R4))
A5: ='Preencher pelo celular'!A8 -> 46291 | B5: =IF('Preencher pelo celular'!C8="","",'Preencher pelo celular'!C8) | C5: =IF('Preencher pelo celular'!D8="","",'Preencher pelo celular'!D8) | D5: =IF('Preencher pelo celular'!F8="","",'Preencher pelo celular'!F8) | E5: =IF('Preencher pelo celular'!C9="","",'Preencher pelo celular'!C9) | F5: =IF('Preencher pelo celular'!D9="","",'Preencher pelo celular'!D9) | G5: =IF('Preencher pelo celular'!F9="","",'Preencher pelo celular'!F9) | H5: =IF('Preencher pelo celular'!C10="","",'Preencher pelo celular'!C10) | I5: =IF('Preencher pelo celular'!D10="","",'Preencher pelo celular'!D10) | J5: =IF('Preencher pelo celular'!F10="","",'Preencher pelo celular'!F10) | K5: =IF('Preencher pelo celular'!C11="","",'Preencher pelo celular'!C11) | L5: =IF('Preencher pelo celular'!D11="","",'Preencher pelo celular'!D11) | M5: =IF('Preencher pelo celular'!F11="","",'Preencher pelo celular'!F11) | N5: =IF('Preencher pelo celular'!C12="","",'Preencher pelo celular'!C12) | O5: =IF('Preencher pelo celular'!D12="","",'Preencher pelo celular'!D12) | P5: =IF('Preencher pelo celular'!F12="","",'Preencher pelo celular'!F12) | Q5: =IF('Preencher pelo celular'!C13="","",'Preencher pelo celular'!C13) | R5: =IF('Preencher pelo celular'!D13="","",'Preencher pelo celular'!D13) | S5: =IF('Preencher pelo celular'!F13="","",'Preencher pelo celular'!F13) | T5: =IF(COUNT(B5,E5,H5,K5,N5,Q5)=0,"",AVERAGE(B5,E5,H5,K5,N5,Q5)) | U5: =IF(COUNT(D5,G5,J5,M5,P5,S5)=0,"",AVERAGE(D5,G5,J5,M5,P5,S5)) | V5: =IF(COUNT(C5,F5,I5,L5,O5,R5)=0,"",SUM(C5,F5,I5,L5,O5,R5))
A6: ='Preencher pelo celular'!A14 -> 46292 | B6: =IF('Preencher pelo celular'!C14="","",'Preencher pelo celular'!C14) | C6: =IF('Preencher pelo celular'!D14="","",'Preencher pelo celular'!D14) | D6: =IF('Preencher pelo celular'!F14="","",'Preencher pelo celular'!F14) | E6: =IF('Preencher pelo celular'!C15="","",'Preencher pelo celular'!C15) | F6: =IF('Preencher pelo celular'!D15="","",'Preencher pelo celular'!D15) | G6: =IF('Preencher pelo celular'!F15="","",'Preencher pelo celular'!F15) | H6: =IF('Preencher pelo celular'!C16="","",'Preencher pelo celular'!C16) | I6: =IF('Preencher pelo celular'!D16="","",'Preencher pelo celular'!D16) | J6: =IF('Preencher pelo celular'!F16="","",'Preencher pelo celular'!F16) | K6: =IF('Preencher pelo celular'!C17="","",'Preencher pelo celular'!C17) | L6: =IF('Preencher pelo celular'!D17="","",'Preencher pelo celular'!D17) | M6: =IF('Preencher pelo celular'!F17="","",'Preencher pelo celular'!F17) | N6: =IF('Preencher pelo celular'!C18="","",'Preencher pelo celular'!C18) | O6: =IF('Preencher pelo celular'!D18="","",'Preencher pelo celular'!D18) | P6: =IF('Preencher pelo celular'!F18="","",'Preencher pelo celular'!F18) | Q6: =IF('Preencher pelo celular'!C19="","",'Preencher pelo celular'!C19) | R6: =IF('Preencher pelo celular'!D19="","",'Preencher pelo celular'!D19) | S6: =IF('Preencher pelo celular'!F19="","",'Preencher pelo celular'!F19) | T6: =IF(COUNT(B6,E6,H6,K6,N6,Q6)=0,"",AVERAGE(B6,E6,H6,K6,N6,Q6)) | U6: =IF(COUNT(D6,G6,J6,M6,P6,S6)=0,"",AVERAGE(D6,G6,J6,M6,P6,S6)) | V6: =IF(COUNT(C6,F6,I6,L6,O6,R6)=0,"",SUM(C6,F6,I6,L6,O6,R6))
A7: ='Preencher pelo celular'!A20 -> 46293 | B7: =IF('Preencher pelo celular'!C20="","",'Preencher pelo celular'!C20) | C7: =IF('Preencher pelo celular'!D20="","",'Preencher pelo celular'!D20) | D7: =IF('Preencher pelo celular'!F20="","",'Preencher pelo celular'!F20) | E7: =IF('Preencher pelo celular'!C21="","",'Preencher pelo celular'!C21) | F7: =IF('Preencher pelo celular'!D21="","",'Preencher pelo celular'!D21) | G7: =IF('Preencher pelo celular'!F21="","",'Preencher pelo celular'!F21) | H7: =IF('Preencher pelo celular'!C22="","",'Preencher pelo celular'!C22) | I7: =IF('Preencher pelo celular'!D22="","",'Preencher pelo celular'!D22) | J7: =IF('Preencher pelo celular'!F22="","",'Preencher pelo celular'!F22) | K7: =IF('Preencher pelo celular'!C23="","",'Preencher pelo celular'!C23) | L7: =IF('Preencher pelo celular'!D23="","",'Preencher pelo celular'!D23) | M7: =IF('Preencher pelo celular'!F23="","",'Preencher pelo celular'!F23) | N7: =IF('Preencher pelo celular'!C24="","",'Preencher pelo celular'!C24) | O7: =IF('Preencher pelo celular'!D24="","",'Preencher pelo celular'!D24) | P7: =IF('Preencher pelo celular'!F24="","",'Preencher pelo celular'!F24) | Q7: =IF('Preencher pelo celular'!C25="","",'Preencher pelo celular'!C25) | R7: =IF('Preencher pelo celular'!D25="","",'Preencher pelo celular'!D25) | S7: =IF('Preencher pelo celular'!F25="","",'Preencher pelo celular'!F25) | T7: =IF(COUNT(B7,E7,H7,K7,N7,Q7)=0,"",AVERAGE(B7,E7,H7,K7,N7,Q7)) | U7: =IF(COUNT(D7,G7,J7,M7,P7,S7)=0,"",AVERAGE(D7,G7,J7,M7,P7,S7)) | V7: =IF(COUNT(C7,F7,I7,L7,O7,R7)=0,"",SUM(C7,F7,I7,L7,O7,R7))
A8: ='Preencher pelo celular'!A26 -> 46294 | B8: =IF('Preencher pelo celular'!C26="","",'Preencher pelo celular'!C26) | C8: =IF('Preencher pelo celular'!D26="","",'Preencher pelo celular'!D26) | D8: =IF('Preencher pelo celular'!F26="","",'Preencher pelo celular'!F26) | E8: =IF('Preencher pelo celular'!C27="","",'Preencher pelo celular'!C27) | F8: =IF('Preencher pelo celular'!D27="","",'Preencher pelo celular'!D27) | G8: =IF('Preencher pelo celular'!F27="","",'Preencher pelo celular'!F27) | H8: =IF('Preencher pelo celular'!C28="","",'Preencher pelo celular'!C28) | I8: =IF('Preencher pelo celular'!D28="","",'Preencher pelo celular'!D28) | J8: =IF('Preencher pelo celular'!F28="","",'Preencher pelo celular'!F28) | K8: =IF('Preencher pelo celular'!C29="","",'Preencher pelo celular'!C29) | L8: =IF('Preencher pelo celular'!D29="","",'Preencher pelo celular'!D29) | M8: =IF('Preencher pelo celular'!F29="","",'Preencher pelo celular'!F29) | N8: =IF('Preencher pelo celular'!C30="","",'Preencher pelo celular'!C30) | O8: =IF('Preencher pelo celular'!D30="","",'Preencher pelo celular'!D30) | P8: =IF('Preencher pelo celular'!F30="","",'Preencher pelo celular'!F30) | Q8: =IF('Preencher pelo celular'!C31="","",'Preencher pelo celular'!C31) | R8: =IF('Preencher pelo celular'!D31="","",'Preencher pelo celular'!D31) | S8: =IF('Preencher pelo celular'!F31="","",'Preencher pelo celular'!F31) | T8: =IF(COUNT(B8,E8,H8,K8,N8,Q8)=0,"",AVERAGE(B8,E8,H8,K8,N8,Q8)) | U8: =IF(COUNT(D8,G8,J8,M8,P8,S8)=0,"",AVERAGE(D8,G8,J8,M8,P8,S8)) | V8: =IF(COUNT(C8,F8,I8,L8,O8,R8)=0,"",SUM(C8,F8,I8,L8,O8,R8))
A9: ='Preencher pelo celular'!A32 -> 46295 | B9: =IF('Preencher pelo celular'!C32="","",'Preencher pelo celular'!C32) | C9: =IF('Preencher pelo celular'!D32="","",'Preencher pelo celular'!D32) | D9: =IF('Preencher pelo celular'!F32="","",'Preencher pelo celular'!F32) | E9: =IF('Preencher pelo celular'!C33="","",'Preencher pelo celular'!C33) | F9: =IF('Preencher pelo celular'!D33="","",'Preencher pelo celular'!D33) | G9: =IF('Preencher pelo celular'!F33="","",'Preencher pelo celular'!F33) | H9: =IF('Preencher pelo celular'!C34="","",'Preencher pelo celular'!C34) | I9: =IF('Preencher pelo celular'!D34="","",'Preencher pelo celular'!D34) | J9: =IF('Preencher pelo celular'!F34="","",'Preencher pelo celular'!F34) | K9: =IF('Preencher pelo celular'!C35="","",'Preencher pelo celular'!C35) | L9: =IF('Preencher pelo celular'!D35="","",'Preencher pelo celular'!D35) | M9: =IF('Preencher pelo celular'!F35="","",'Preencher pelo celular'!F35) | N9: =IF('Preencher pelo celular'!C36="","",'Preencher pelo celular'!C36) | O9: =IF('Preencher pelo celular'!D36="","",'Preencher pelo celular'!D36) | P9: =IF('Preencher pelo celular'!F36="","",'Preencher pelo celular'!F36) | Q9: =IF('Preencher pelo celular'!C37="","",'Preencher pelo celular'!C37) | R9: =IF('Preencher pelo celular'!D37="","",'Preencher pelo celular'!D37) | S9: =IF('Preencher pelo celular'!F37="","",'Preencher pelo celular'!F37) | T9: =IF(COUNT(B9,E9,H9,K9,N9,Q9)=0,"",AVERAGE(B9,E9,H9,K9,N9,Q9)) | U9: =IF(COUNT(D9,G9,J9,M9,P9,S9)=0,"",AVERAGE(D9,G9,J9,M9,P9,S9)) | V9: =IF(COUNT(C9,F9,I9,L9,O9,R9)=0,"",SUM(C9,F9,I9,L9,O9,R9))
A10: ='Preencher pelo celular'!A38 -> 46296 | B10: =IF('Preencher pelo celular'!C38="","",'Preencher pelo celular'!C38) | C10: =IF('Preencher pelo celular'!D38="","",'Preencher pelo celular'!D38) | D10: =IF('Preencher pelo celular'!F38="","",'Preencher pelo celular'!F38) | E10: =IF('Preencher pelo celular'!C39="","",'Preencher pelo celular'!C39) | F10: =IF('Preencher pelo celular'!D39="","",'Preencher pelo celular'!D39) | G10: =IF('Preencher pelo celular'!F39="","",'Preencher pelo celular'!F39) | H10: =IF('Preencher pelo celular'!C40="","",'Preencher pelo celular'!C40) | I10: =IF('Preencher pelo celular'!D40="","",'Preencher pelo celular'!D40) | J10: =IF('Preencher pelo celular'!F40="","",'Preencher pelo celular'!F40) | K10: =IF('Preencher pelo celular'!C41="","",'Preencher pelo celular'!C41) | L10: =IF('Preencher pelo celular'!D41="","",'Preencher pelo celular'!D41) | M10: =IF('Preencher pelo celular'!F41="","",'Preencher pelo celular'!F41) | N10: =IF('Preencher pelo celular'!C42="","",'Preencher pelo celular'!C42) | O10: =IF('Preencher pelo celular'!D42="","",'Preencher pelo celular'!D42) | P10: =IF('Preencher pelo celular'!F42="","",'Preencher pelo celular'!F42) | Q10: =IF('Preencher pelo celular'!C43="","",'Preencher pelo celular'!C43) | R10: =IF('Preencher pelo celular'!D43="","",'Preencher pelo celular'!D43) | S10: =IF('Preencher pelo celular'!F43="","",'Preencher pelo celular'!F43) | T10: =IF(COUNT(B10,E10,H10,K10,N10,Q10)=0,"",AVERAGE(B10,E10,H10,K10,N10,Q10)) | U10: =IF(COUNT(D10,G10,J10,M10,P10,S10)=0,"",AVERAGE(D10,G10,J10,M10,P10,S10)) | V10: =IF(COUNT(C10,F10,I10,L10,O10,R10)=0,"",SUM(C10,F10,I10,L10,O10,R10))
A11: ='Preencher pelo celular'!A44 -> 46297 | B11: =IF('Preencher pelo celular'!C44="","",'Preencher pelo celular'!C44) | C11: =IF('Preencher pelo celular'!D44="","",'Preencher pelo celular'!D44) | D11: =IF('Preencher pelo celular'!F44="","",'Preencher pelo celular'!F44) | E11: =IF('Preencher pelo celular'!C45="","",'Preencher pelo celular'!C45) | F11: =IF('Preencher pelo celular'!D45="","",'Preencher pelo celular'!D45) | G11: =IF('Preencher pelo celular'!F45="","",'Preencher pelo celular'!F45) | H11: =IF('Preencher pelo celular'!C46="","",'Preencher pelo celular'!C46) | I11: =IF('Preencher pelo celular'!D46="","",'Preencher pelo celular'!D46) | J11: =IF('Preencher pelo celular'!F46="","",'Preencher pelo celular'!F46) | K11: =IF('Preencher pelo celular'!C47="","",'Preencher pelo celular'!C47) | L11: =IF('Preencher pelo celular'!D47="","",'Preencher pelo celular'!D47) | M11: =IF('Preencher pelo celular'!F47="","",'Preencher pelo celular'!F47) | N11: =IF('Preencher pelo celular'!C48="","",'Preencher pelo celular'!C48) | O11: =IF('Preencher pelo celular'!D48="","",'Preencher pelo celular'!D48) | P11: =IF('Preencher pelo celular'!F48="","",'Preencher pelo celular'!F48) | Q11: =IF('Preencher pelo celular'!C49="","",'Preencher pelo celular'!C49) | R11: =IF('Preencher pelo celular'!D49="","",'Preencher pelo celular'!D49) | S11: =IF('Preencher pelo celular'!F49="","",'Preencher pelo celular'!F49) | T11: =IF(COUNT(B11,E11,H11,K11,N11,Q11)=0,"",AVERAGE(B11,E11,H11,K11,N11,Q11)) | U11: =IF(COUNT(D11,G11,J11,M11,P11,S11)=0,"",AVERAGE(D11,G11,J11,M11,P11,S11)) | V11: =IF(COUNT(C11,F11,I11,L11,O11,R11)=0,"",SUM(C11,F11,I11,L11,O11,R11))
A12: ='Preencher pelo celular'!A50 -> 46298 | B12: =IF('Preencher pelo celular'!C50="","",'Preencher pelo celular'!C50) | C12: =IF('Preencher pelo celular'!D50="","",'Preencher pelo celular'!D50) | D12: =IF('Preencher pelo celular'!F50="","",'Preencher pelo celular'!F50) | E12: =IF('Preencher pelo celular'!C51="","",'Preencher pelo celular'!C51) | F12: =IF('Preencher pelo celular'!D51="","",'Preencher pelo celular'!D51) | G12: =IF('Preencher pelo celular'!F51="","",'Preencher pelo celular'!F51) | H12: =IF('Preencher pelo celular'!C52="","",'Preencher pelo celular'!C52) | I12: =IF('Preencher pelo celular'!D52="","",'Preencher pelo celular'!D52) | J12: =IF('Preencher pelo celular'!F52="","",'Preencher pelo celular'!F52) | K12: =IF('Preencher pelo celular'!C53="","",'Preencher pelo celular'!C53) | L12: =IF('Preencher pelo celular'!D53="","",'Preencher pelo celular'!D53) | M12: =IF('Preencher pelo celular'!F53="","",'Preencher pelo celular'!F53) | N12: =IF('Preencher pelo celular'!C54="","",'Preencher pelo celular'!C54) | O12: =IF('Preencher pelo celular'!D54="","",'Preencher pelo celular'!D54) | P12: =IF('Preencher pelo celular'!F54="","",'Preencher pelo celular'!F54) | Q12: =IF('Preencher pelo celular'!C55="","",'Preencher pelo celular'!C55) | R12: =IF('Preencher pelo celular'!D55="","",'Preencher pelo celular'!D55) | S12: =IF('Preencher pelo celular'!F55="","",'Preencher pelo celular'!F55) | T12: =IF(COUNT(B12,E12,H12,K12,N12,Q12)=0,"",AVERAGE(B12,E12,H12,K12,N12,Q12)) | U12: =IF(COUNT(D12,G12,J12,M12,P12,S12)=0,"",AVERAGE(D12,G12,J12,M12,P12,S12)) | V12: =IF(COUNT(C12,F12,I12,L12,O12,R12)=0,"",SUM(C12,F12,I12,L12,O12,R12))
A13: ='Preencher pelo celular'!A56 -> 46299 | B13: =IF('Preencher pelo celular'!C56="","",'Preencher pelo celular'!C56) | C13: =IF('Preencher pelo celular'!D56="","",'Preencher pelo celular'!D56) | D13: =IF('Preencher pelo celular'!F56="","",'Preencher pelo celular'!F56) | E13: =IF('Preencher pelo celular'!C57="","",'Preencher pelo celular'!C57) | F13: =IF('Preencher pelo celular'!D57="","",'Preencher pelo celular'!D57) | G13: =IF('Preencher pelo celular'!F57="","",'Preencher pelo celular'!F57) | H13: =IF('Preencher pelo celular'!C58="","",'Preencher pelo celular'!C58) | I13: =IF('Preencher pelo celular'!D58="","",'Preencher pelo celular'!D58) | J13: =IF('Preencher pelo celular'!F58="","",'Preencher pelo celular'!F58) | K13: =IF('Preencher pelo celular'!C59="","",'Preencher pelo celular'!C59) | L13: =IF('Preencher pelo celular'!D59="","",'Preencher pelo celular'!D59) | M13: =IF('Preencher pelo celular'!F59="","",'Preencher pelo celular'!F59) | N13: =IF('Preencher pelo celular'!C60="","",'Preencher pelo celular'!C60) | O13: =IF('Preencher pelo celular'!D60="","",'Preencher pelo celular'!D60) | P13: =IF('Preencher pelo celular'!F60="","",'Preencher pelo celular'!F60) | Q13: =IF('Preencher pelo celular'!C61="","",'Preencher pelo celular'!C61) | R13: =IF('Preencher pelo celular'!D61="","",'Preencher pelo celular'!D61) | S13: =IF('Preencher pelo celular'!F61="","",'Preencher pelo celular'!F61) | T13: =IF(COUNT(B13,E13,H13,K13,N13,Q13)=0,"",AVERAGE(B13,E13,H13,K13,N13,Q13)) | U13: =IF(COUNT(D13,G13,J13,M13,P13,S13)=0,"",AVERAGE(D13,G13,J13,M13,P13,S13)) | V13: =IF(COUNT(C13,F13,I13,L13,O13,R13)=0,"",SUM(C13,F13,I13,L13,O13,R13))
A14: ='Preencher pelo celular'!A62 -> 46300 | B14: =IF('Preencher pelo celular'!C62="","",'Preencher pelo celular'!C62) | C14: =IF('Preencher pelo celular'!D62="","",'Preencher pelo celular'!D62) | D14: =IF('Preencher pelo celular'!F62="","",'Preencher pelo celular'!F62) | E14: =IF('Preencher pelo celular'!C63="","",'Preencher pelo celular'!C63) | F14: =IF('Preencher pelo celular'!D63="","",'Preencher pelo celular'!D63) | G14: =IF('Preencher pelo celular'!F63="","",'Preencher pelo celular'!F63) | H14: =IF('Preencher pelo celular'!C64="","",'Preencher pelo celular'!C64) | I14: =IF('Preencher pelo celular'!D64="","",'Preencher pelo celular'!D64) | J14: =IF('Preencher pelo celular'!F64="","",'Preencher pelo celular'!F64) | K14: =IF('Preencher pelo celular'!C65="","",'Preencher pelo celular'!C65) | L14: =IF('Preencher pelo celular'!D65="","",'Preencher pelo celular'!D65) | M14: =IF('Preencher pelo celular'!F65="","",'Preencher pelo celular'!F65) | N14: =IF('Preencher pelo celular'!C66="","",'Preencher pelo celular'!C66) | O14: =IF('Preencher pelo celular'!D66="","",'Preencher pelo celular'!D66) | P14: =IF('Preencher pelo celular'!F66="","",'Preencher pelo celular'!F66) | Q14: =IF('Preencher pelo celular'!C67="","",'Preencher pelo celular'!C67) | R14: =IF('Preencher pelo celular'!D67="","",'Preencher pelo celular'!D67) | S14: =IF('Preencher pelo celular'!F67="","",'Preencher pelo celular'!F67) | T14: =IF(COUNT(B14,E14,H14,K14,N14,Q14)=0,"",AVERAGE(B14,E14,H14,K14,N14,Q14)) | U14: =IF(COUNT(D14,G14,J14,M14,P14,S14)=0,"",AVERAGE(D14,G14,J14,M14,P14,S14)) | V14: =IF(COUNT(C14,F14,I14,L14,O14,R14)=0,"",SUM(C14,F14,I14,L14,O14,R14))
A15: ='Preencher pelo celular'!A68 -> 46301 | B15: =IF('Preencher pelo celular'!C68="","",'Preencher pelo celular'!C68) | C15: =IF('Preencher pelo celular'!D68="","",'Preencher pelo celular'!D68) | D15: =IF('Preencher pelo celular'!F68="","",'Preencher pelo celular'!F68) | E15: =IF('Preencher pelo celular'!C69="","",'Preencher pelo celular'!C69) | F15: =IF('Preencher pelo celular'!D69="","",'Preencher pelo celular'!D69) | G15: =IF('Preencher pelo celular'!F69="","",'Preencher pelo celular'!F69) | H15: =IF('Preencher pelo celular'!C70="","",'Preencher pelo celular'!C70) | I15: =IF('Preencher pelo celular'!D70="","",'Preencher pelo celular'!D70) | J15: =IF('Preencher pelo celular'!F70="","",'Preencher pelo celular'!F70) | K15: =IF('Preencher pelo celular'!C71="","",'Preencher pelo celular'!C71) | L15: =IF('Preencher pelo celular'!D71="","",'Preencher pelo celular'!D71) | M15: =IF('Preencher pelo celular'!F71="","",'Preencher pelo celular'!F71) | N15: =IF('Preencher pelo celular'!C72="","",'Preencher pelo celular'!C72) | O15: =IF('Preencher pelo celular'!D72="","",'Preencher pelo celular'!D72) | P15: =IF('Preencher pelo celular'!F72="","",'Preencher pelo celular'!F72) | Q15: =IF('Preencher pelo celular'!C73="","",'Preencher pelo celular'!C73) | R15: =IF('Preencher pelo celular'!D73="","",'Preencher pelo celular'!D73) | S15: =IF('Preencher pelo celular'!F73="","",'Preencher pelo celular'!F73) | T15: =IF(COUNT(B15,E15,H15,K15,N15,Q15)=0,"",AVERAGE(B15,E15,H15,K15,N15,Q15)) | U15: =IF(COUNT(D15,G15,J15,M15,P15,S15)=0,"",AVERAGE(D15,G15,J15,M15,P15,S15)) | V15: =IF(COUNT(C15,F15,I15,L15,O15,R15)=0,"",SUM(C15,F15,I15,L15,O15,R15))
A16: ='Preencher pelo celular'!A74 -> 46302 | B16: =IF('Preencher pelo celular'!C74="","",'Preencher pelo celular'!C74) | C16: =IF('Preencher pelo celular'!D74="","",'Preencher pelo celular'!D74) | D16: =IF('Preencher pelo celular'!F74="","",'Preencher pelo celular'!F74) | E16: =IF('Preencher pelo celular'!C75="","",'Preencher pelo celular'!C75) | F16: =IF('Preencher pelo celular'!D75="","",'Preencher pelo celular'!D75) | G16: =IF('Preencher pelo celular'!F75="","",'Preencher pelo celular'!F75) | H16: =IF('Preencher pelo celular'!C76="","",'Preencher pelo celular'!C76) | I16: =IF('Preencher pelo celular'!D76="","",'Preencher pelo celular'!D76) | J16: =IF('Preencher pelo celular'!F76="","",'Preencher pelo celular'!F76) | K16: =IF('Preencher pelo celular'!C77="","",'Preencher pelo celular'!C77) | L16: =IF('Preencher pelo celular'!D77="","",'Preencher pelo celular'!D77) | M16: =IF('Preencher pelo celular'!F77="","",'Preencher pelo celular'!F77) | N16: =IF('Preencher pelo celular'!C78="","",'Preencher pelo celular'!C78) | O16: =IF('Preencher pelo celular'!D78="","",'Preencher pelo celular'!D78) | P16: =IF('Preencher pelo celular'!F78="","",'Preencher pelo celular'!F78) | Q16: =IF('Preencher pelo celular'!C79="","",'Preencher pelo celular'!C79) | R16: =IF('Preencher pelo celular'!D79="","",'Preencher pelo celular'!D79) | S16: =IF('Preencher pelo celular'!F79="","",'Preencher pelo celular'!F79) | T16: =IF(COUNT(B16,E16,H16,K16,N16,Q16)=0,"",AVERAGE(B16,E16,H16,K16,N16,Q16)) | U16: =IF(COUNT(D16,G16,J16,M16,P16,S16)=0,"",AVERAGE(D16,G16,J16,M16,P16,S16)) | V16: =IF(COUNT(C16,F16,I16,L16,O16,R16)=0,"",SUM(C16,F16,I16,L16,O16,R16))
A17: ='Preencher pelo celular'!A80 -> 46303 | B17: =IF('Preencher pelo celular'!C80="","",'Preencher pelo celular'!C80) | C17: =IF('Preencher pelo celular'!D80="","",'Preencher pelo celular'!D80) | D17: =IF('Preencher pelo celular'!F80="","",'Preencher pelo celular'!F80) | E17: =IF('Preencher pelo celular'!C81="","",'Preencher pelo celular'!C81) | F17: =IF('Preencher pelo celular'!D81="","",'Preencher pelo celular'!D81) | G17: =IF('Preencher pelo celular'!F81="","",'Preencher pelo celular'!F81) | H17: =IF('Preencher pelo celular'!C82="","",'Preencher pelo celular'!C82) | I17: =IF('Preencher pelo celular'!D82="","",'Preencher pelo celular'!D82) | J17: =IF('Preencher pelo celular'!F82="","",'Preencher pelo celular'!F82) | K17: =IF('Preencher pelo celular'!C83="","",'Preencher pelo celular'!C83) | L17: =IF('Preencher pelo celular'!D83="","",'Preencher pelo celular'!D83) | M17: =IF('Preencher pelo celular'!F83="","",'Preencher pelo celular'!F83) | N17: =IF('Preencher pelo celular'!C84="","",'Preencher pelo celular'!C84) | O17: =IF('Preencher pelo celular'!D84="","",'Preencher pelo celular'!D84) | P17: =IF('Preencher pelo celular'!F84="","",'Preencher pelo celular'!F84) | Q17: =IF('Preencher pelo celular'!C85="","",'Preencher pelo celular'!C85) | R17: =IF('Preencher pelo celular'!D85="","",'Preencher pelo celular'!D85) | S17: =IF('Preencher pelo celular'!F85="","",'Preencher pelo celular'!F85) | T17: =IF(COUNT(B17,E17,H17,K17,N17,Q17)=0,"",AVERAGE(B17,E17,H17,K17,N17,Q17)) | U17: =IF(COUNT(D17,G17,J17,M17,P17,S17)=0,"",AVERAGE(D17,G17,J17,M17,P17,S17)) | V17: =IF(COUNT(C17,F17,I17,L17,O17,R17)=0,"",SUM(C17,F17,I17,L17,O17,R17))
A18: ='Preencher pelo celular'!A86 -> 46304 | B18: =IF('Preencher pelo celular'!C86="","",'Preencher pelo celular'!C86) | C18: =IF('Preencher pelo celular'!D86="","",'Preencher pelo celular'!D86) | D18: =IF('Preencher pelo celular'!F86="","",'Preencher pelo celular'!F86) | E18: =IF('Preencher pelo celular'!C87="","",'Preencher pelo celular'!C87) | F18: =IF('Preencher pelo celular'!D87="","",'Preencher pelo celular'!D87) | G18: =IF('Preencher pelo celular'!F87="","",'Preencher pelo celular'!F87) | H18: =IF('Preencher pelo celular'!C88="","",'Preencher pelo celular'!C88) | I18: =IF('Preencher pelo celular'!D88="","",'Preencher pelo celular'!D88) | J18: =IF('Preencher pelo celular'!F88="","",'Preencher pelo celular'!F88) | K18: =IF('Preencher pelo celular'!C89="","",'Preencher pelo celular'!C89) | L18: =IF('Preencher pelo celular'!D89="","",'Preencher pelo celular'!D89) | M18: =IF('Preencher pelo celular'!F89="","",'Preencher pelo celular'!F89) | N18: =IF('Preencher pelo celular'!C90="","",'Preencher pelo celular'!C90) | O18: =IF('Preencher pelo celular'!D90="","",'Preencher pelo celular'!D90) | P18: =IF('Preencher pelo celular'!F90="","",'Preencher pelo celular'!F90) | Q18: =IF('Preencher pelo celular'!C91="","",'Preencher pelo celular'!C91) | R18: =IF('Preencher pelo celular'!D91="","",'Preencher pelo celular'!D91) | S18: =IF('Preencher pelo celular'!F91="","",'Preencher pelo celular'!F91) | T18: =IF(COUNT(B18,E18,H18,K18,N18,Q18)=0,"",AVERAGE(B18,E18,H18,K18,N18,Q18)) | U18: =IF(COUNT(D18,G18,J18,M18,P18,S18)=0,"",AVERAGE(D18,G18,J18,M18,P18,S18)) | V18: =IF(COUNT(C18,F18,I18,L18,O18,R18)=0,"",SUM(C18,F18,I18,L18,O18,R18))
A19: ='Preencher pelo celular'!A92 -> 46305 | B19: =IF('Preencher pelo celular'!C92="","",'Preencher pelo celular'!C92) | C19: =IF('Preencher pelo celular'!D92="","",'Preencher pelo celular'!D92) | D19: =IF('Preencher pelo celular'!F92="","",'Preencher pelo celular'!F92) | E19: =IF('Preencher pelo celular'!C93="","",'Preencher pelo celular'!C93) | F19: =IF('Preencher pelo celular'!D93="","",'Preencher pelo celular'!D93) | G19: =IF('Preencher pelo celular'!F93="","",'Preencher pelo celular'!F93) | H19: =IF('Preencher pelo celular'!C94="","",'Preencher pelo celular'!C94) | I19: =IF('Preencher pelo celular'!D94="","",'Preencher pelo celular'!D94) | J19: =IF('Preencher pelo celular'!F94="","",'Preencher pelo celular'!F94) | K19: =IF('Preencher pelo celular'!C95="","",'Preencher pelo celular'!C95) | L19: =IF('Preencher pelo celular'!D95="","",'Preencher pelo celular'!D95) | M19: =IF('Preencher pelo celular'!F95="","",'Preencher pelo celular'!F95) | N19: =IF('Preencher pelo celular'!C96="","",'Preencher pelo celular'!C96) | O19: =IF('Preencher pelo celular'!D96="","",'Preencher pelo celular'!D96) | P19: =IF('Preencher pelo celular'!F96="","",'Preencher pelo celular'!F96) | Q19: =IF('Preencher pelo celular'!C97="","",'Preencher pelo celular'!C97) | R19: =IF('Preencher pelo celular'!D97="","",'Preencher pelo celular'!D97) | S19: =IF('Preencher pelo celular'!F97="","",'Preencher pelo celular'!F97) | T19: =IF(COUNT(B19,E19,H19,K19,N19,Q19)=0,"",AVERAGE(B19,E19,H19,K19,N19,Q19)) | U19: =IF(COUNT(D19,G19,J19,M19,P19,S19)=0,"",AVERAGE(D19,G19,J19,M19,P19,S19)) | V19: =IF(COUNT(C19,F19,I19,L19,O19,R19)=0,"",SUM(C19,F19,I19,L19,O19,R19))
A20: ='Preencher pelo celular'!A98 -> 46306 | B20: =IF('Preencher pelo celular'!C98="","",'Preencher pelo celular'!C98) | C20: =IF('Preencher pelo celular'!D98="","",'Preencher pelo celular'!D98) | D20: =IF('Preencher pelo celular'!F98="","",'Preencher pelo celular'!F98) | E20: =IF('Preencher pelo celular'!C99="","",'Preencher pelo celular'!C99) | F20: =IF('Preencher pelo celular'!D99="","",'Preencher pelo celular'!D99) | G20: =IF('Preencher pelo celular'!F99="","",'Preencher pelo celular'!F99) | H20: =IF('Preencher pelo celular'!C100="","",'Preencher pelo celular'!C100) | I20: =IF('Preencher pelo celular'!D100="","",'Preencher pelo celular'!D100) | J20: =IF('Preencher pelo celular'!F100="","",'Preencher pelo celular'!F100) | K20: =IF('Preencher pelo celular'!C101="","",'Preencher pelo celular'!C101) | L20: =IF('Preencher pelo celular'!D101="","",'Preencher pelo celular'!D101) | M20: =IF('Preencher pelo celular'!F101="","",'Preencher pelo celular'!F101) | N20: =IF('Preencher pelo celular'!C102="","",'Preencher pelo celular'!C102) | O20: =IF('Preencher pelo celular'!D102="","",'Preencher pelo celular'!D102) | P20: =IF('Preencher pelo celular'!F102="","",'Preencher pelo celular'!F102) | Q20: =IF('Preencher pelo celular'!C103="","",'Preencher pelo celular'!C103) | R20: =IF('Preencher pelo celular'!D103="","",'Preencher pelo celular'!D103) | S20: =IF('Preencher pelo celular'!F103="","",'Preencher pelo celular'!F103) | T20: =IF(COUNT(B20,E20,H20,K20,N20,Q20)=0,"",AVERAGE(B20,E20,H20,K20,N20,Q20)) | U20: =IF(COUNT(D20,G20,J20,M20,P20,S20)=0,"",AVERAGE(D20,G20,J20,M20,P20,S20)) | V20: =IF(COUNT(C20,F20,I20,L20,O20,R20)=0,"",SUM(C20,F20,I20,L20,O20,R20))
A21: ='Preencher pelo celular'!A104 -> 46307 | B21: =IF('Preencher pelo celular'!C104="","",'Preencher pelo celular'!C104) | C21: =IF('Preencher pelo celular'!D104="","",'Preencher pelo celular'!D104) | D21: =IF('Preencher pelo celular'!F104="","",'Preencher pelo celular'!F104) | E21: =IF('Preencher pelo celular'!C105="","",'Preencher pelo celular'!C105) | F21: =IF('Preencher pelo celular'!D105="","",'Preencher pelo celular'!D105) | G21: =IF('Preencher pelo celular'!F105="","",'Preencher pelo celular'!F105) | H21: =IF('Preencher pelo celular'!C106="","",'Preencher pelo celular'!C106) | I21: =IF('Preencher pelo celular'!D106="","",'Preencher pelo celular'!D106) | J21: =IF('Preencher pelo celular'!F106="","",'Preencher pelo celular'!F106) | K21: =IF('Preencher pelo celular'!C107="","",'Preencher pelo celular'!C107) | L21: =IF('Preencher pelo celular'!D107="","",'Preencher pelo celular'!D107) | M21: =IF('Preencher pelo celular'!F107="","",'Preencher pelo celular'!F107) | N21: =IF('Preencher pelo celular'!C108="","",'Preencher pelo celular'!C108) | O21: =IF('Preencher pelo celular'!D108="","",'Preencher pelo celular'!D108) | P21: =IF('Preencher pelo celular'!F108="","",'Preencher pelo celular'!F108) | Q21: =IF('Preencher pelo celular'!C109="","",'Preencher pelo celular'!C109) | R21: =IF('Preencher pelo celular'!D109="","",'Preencher pelo celular'!D109) | S21: =IF('Preencher pelo celular'!F109="","",'Preencher pelo celular'!F109) | T21: =IF(COUNT(B21,E21,H21,K21,N21,Q21)=0,"",AVERAGE(B21,E21,H21,K21,N21,Q21)) | U21: =IF(COUNT(D21,G21,J21,M21,P21,S21)=0,"",AVERAGE(D21,G21,J21,M21,P21,S21)) | V21: =IF(COUNT(C21,F21,I21,L21,O21,R21)=0,"",SUM(C21,F21,I21,L21,O21,R21))
A22: ='Preencher pelo celular'!A110 -> 46308 | B22: =IF('Preencher pelo celular'!C110="","",'Preencher pelo celular'!C110) | C22: =IF('Preencher pelo celular'!D110="","",'Preencher pelo celular'!D110) | D22: =IF('Preencher pelo celular'!F110="","",'Preencher pelo celular'!F110) | E22: =IF('Preencher pelo celular'!C111="","",'Preencher pelo celular'!C111) | F22: =IF('Preencher pelo celular'!D111="","",'Preencher pelo celular'!D111) | G22: =IF('Preencher pelo celular'!F111="","",'Preencher pelo celular'!F111) | H22: =IF('Preencher pelo celular'!C112="","",'Preencher pelo celular'!C112) | I22: =IF('Preencher pelo celular'!D112="","",'Preencher pelo celular'!D112) | J22: =IF('Preencher pelo celular'!F112="","",'Preencher pelo celular'!F112) | K22: =IF('Preencher pelo celular'!C113="","",'Preencher pelo celular'!C113) | L22: =IF('Preencher pelo celular'!D113="","",'Preencher pelo celular'!D113) | M22: =IF('Preencher pelo celular'!F113="","",'Preencher pelo celular'!F113) | N22: =IF('Preencher pelo celular'!C114="","",'Preencher pelo celular'!C114) | O22: =IF('Preencher pelo celular'!D114="","",'Preencher pelo celular'!D114) | P22: =IF('Preencher pelo celular'!F114="","",'Preencher pelo celular'!F114) | Q22: =IF('Preencher pelo celular'!C115="","",'Preencher pelo celular'!C115) | R22: =IF('Preencher pelo celular'!D115="","",'Preencher pelo celular'!D115) | S22: =IF('Preencher pelo celular'!F115="","",'Preencher pelo celular'!F115) | T22: =IF(COUNT(B22,E22,H22,K22,N22,Q22)=0,"",AVERAGE(B22,E22,H22,K22,N22,Q22)) | U22: =IF(COUNT(D22,G22,J22,M22,P22,S22)=0,"",AVERAGE(D22,G22,J22,M22,P22,S22)) | V22: =IF(COUNT(C22,F22,I22,L22,O22,R22)=0,"",SUM(C22,F22,I22,L22,O22,R22))
A23: ='Preencher pelo celular'!A116 -> 46309 | B23: =IF('Preencher pelo celular'!C116="","",'Preencher pelo celular'!C116) | C23: =IF('Preencher pelo celular'!D116="","",'Preencher pelo celular'!D116) | D23: =IF('Preencher pelo celular'!F116="","",'Preencher pelo celular'!F116) | E23: =IF('Preencher pelo celular'!C117="","",'Preencher pelo celular'!C117) | F23: =IF('Preencher pelo celular'!D117="","",'Preencher pelo celular'!D117) | G23: =IF('Preencher pelo celular'!F117="","",'Preencher pelo celular'!F117) | H23: =IF('Preencher pelo celular'!C118="","",'Preencher pelo celular'!C118) | I23: =IF('Preencher pelo celular'!D118="","",'Preencher pelo celular'!D118) | J23: =IF('Preencher pelo celular'!F118="","",'Preencher pelo celular'!F118) | K23: =IF('Preencher pelo celular'!C119="","",'Preencher pelo celular'!C119) | L23: =IF('Preencher pelo celular'!D119="","",'Preencher pelo celular'!D119) | M23: =IF('Preencher pelo celular'!F119="","",'Preencher pelo celular'!F119) | N23: =IF('Preencher pelo celular'!C120="","",'Preencher pelo celular'!C120) | O23: =IF('Preencher pelo celular'!D120="","",'Preencher pelo celular'!D120) | P23: =IF('Preencher pelo celular'!F120="","",'Preencher pelo celular'!F120) | Q23: =IF('Preencher pelo celular'!C121="","",'Preencher pelo celular'!C121) | R23: =IF('Preencher pelo celular'!D121="","",'Preencher pelo celular'!D121) | S23: =IF('Preencher pelo celular'!F121="","",'Preencher pelo celular'!F121) | T23: =IF(COUNT(B23,E23,H23,K23,N23,Q23)=0,"",AVERAGE(B23,E23,H23,K23,N23,Q23)) | U23: =IF(COUNT(D23,G23,J23,M23,P23,S23)=0,"",AVERAGE(D23,G23,J23,M23,P23,S23)) | V23: =IF(COUNT(C23,F23,I23,L23,O23,R23)=0,"",SUM(C23,F23,I23,L23,O23,R23))
A24: ='Preencher pelo celular'!A122 -> 46310 | B24: =IF('Preencher pelo celular'!C122="","",'Preencher pelo celular'!C122) | C24: =IF('Preencher pelo celular'!D122="","",'Preencher pelo celular'!D122) | D24: =IF('Preencher pelo celular'!F122="","",'Preencher pelo celular'!F122) | E24: =IF('Preencher pelo celular'!C123="","",'Preencher pelo celular'!C123) | F24: =IF('Preencher pelo celular'!D123="","",'Preencher pelo celular'!D123) | G24: =IF('Preencher pelo celular'!F123="","",'Preencher pelo celular'!F123) | H24: =IF('Preencher pelo celular'!C124="","",'Preencher pelo celular'!C124) | I24: =IF('Preencher pelo celular'!D124="","",'Preencher pelo celular'!D124) | J24: =IF('Preencher pelo celular'!F124="","",'Preencher pelo celular'!F124) | K24: =IF('Preencher pelo celular'!C125="","",'Preencher pelo celular'!C125) | L24: =IF('Preencher pelo celular'!D125="","",'Preencher pelo celular'!D125) | M24: =IF('Preencher pelo celular'!F125="","",'Preencher pelo celular'!F125) | N24: =IF('Preencher pelo celular'!C126="","",'Preencher pelo celular'!C126) | O24: =IF('Preencher pelo celular'!D126="","",'Preencher pelo celular'!D126) | P24: =IF('Preencher pelo celular'!F126="","",'Preencher pelo celular'!F126) | Q24: =IF('Preencher pelo celular'!C127="","",'Preencher pelo celular'!C127) | R24: =IF('Preencher pelo celular'!D127="","",'Preencher pelo celular'!D127) | S24: =IF('Preencher pelo celular'!F127="","",'Preencher pelo celular'!F127) | T24: =IF(COUNT(B24,E24,H24,K24,N24,Q24)=0,"",AVERAGE(B24,E24,H24,K24,N24,Q24)) | U24: =IF(COUNT(D24,G24,J24,M24,P24,S24)=0,"",AVERAGE(D24,G24,J24,M24,P24,S24)) | V24: =IF(COUNT(C24,F24,I24,L24,O24,R24)=0,"",SUM(C24,F24,I24,L24,O24,R24))
A25: ='Preencher pelo celular'!A128 -> 46311 | B25: =IF('Preencher pelo celular'!C128="","",'Preencher pelo celular'!C128) | C25: =IF('Preencher pelo celular'!D128="","",'Preencher pelo celular'!D128) | D25: =IF('Preencher pelo celular'!F128="","",'Preencher pelo celular'!F128) | E25: =IF('Preencher pelo celular'!C129="","",'Preencher pelo celular'!C129) | F25: =IF('Preencher pelo celular'!D129="","",'Preencher pelo celular'!D129) | G25: =IF('Preencher pelo celular'!F129="","",'Preencher pelo celular'!F129) | H25: =IF('Preencher pelo celular'!C130="","",'Preencher pelo celular'!C130) | I25: =IF('Preencher pelo celular'!D130="","",'Preencher pelo celular'!D130) | J25: =IF('Preencher pelo celular'!F130="","",'Preencher pelo celular'!F130) | K25: =IF('Preencher pelo celular'!C131="","",'Preencher pelo celular'!C131) | L25: =IF('Preencher pelo celular'!D131="","",'Preencher pelo celular'!D131) | M25: =IF('Preencher pelo celular'!F131="","",'Preencher pelo celular'!F131) | N25: =IF('Preencher pelo celular'!C132="","",'Preencher pelo celular'!C132) | O25: =IF('Preencher pelo celular'!D132="","",'Preencher pelo celular'!D132) | P25: =IF('Preencher pelo celular'!F132="","",'Preencher pelo celular'!F132) | Q25: =IF('Preencher pelo celular'!C133="","",'Preencher pelo celular'!C133) | R25: =IF('Preencher pelo celular'!D133="","",'Preencher pelo celular'!D133) | S25: =IF('Preencher pelo celular'!F133="","",'Preencher pelo celular'!F133) | T25: =IF(COUNT(B25,E25,H25,K25,N25,Q25)=0,"",AVERAGE(B25,E25,H25,K25,N25,Q25)) | U25: =IF(COUNT(D25,G25,J25,M25,P25,S25)=0,"",AVERAGE(D25,G25,J25,M25,P25,S25)) | V25: =IF(COUNT(C25,F25,I25,L25,O25,R25)=0,"",SUM(C25,F25,I25,L25,O25,R25))
A26: ='Preencher pelo celular'!A134 -> 46312 | B26: =IF('Preencher pelo celular'!C134="","",'Preencher pelo celular'!C134) | C26: =IF('Preencher pelo celular'!D134="","",'Preencher pelo celular'!D134) | D26: =IF('Preencher pelo celular'!F134="","",'Preencher pelo celular'!F134) | E26: =IF('Preencher pelo celular'!C135="","",'Preencher pelo celular'!C135) | F26: =IF('Preencher pelo celular'!D135="","",'Preencher pelo celular'!D135) | G26: =IF('Preencher pelo celular'!F135="","",'Preencher pelo celular'!F135) | H26: =IF('Preencher pelo celular'!C136="","",'Preencher pelo celular'!C136) | I26: =IF('Preencher pelo celular'!D136="","",'Preencher pelo celular'!D136) | J26: =IF('Preencher pelo celular'!F136="","",'Preencher pelo celular'!F136) | K26: =IF('Preencher pelo celular'!C137="","",'Preencher pelo celular'!C137) | L26: =IF('Preencher pelo celular'!D137="","",'Preencher pelo celular'!D137) | M26: =IF('Preencher pelo celular'!F137="","",'Preencher pelo celular'!F137) | N26: =IF('Preencher pelo celular'!C138="","",'Preencher pelo celular'!C138) | O26: =IF('Preencher pelo celular'!D138="","",'Preencher pelo celular'!D138) | P26: =IF('Preencher pelo celular'!F138="","",'Preencher pelo celular'!F138) | Q26: =IF('Preencher pelo celular'!C139="","",'Preencher pelo celular'!C139) | R26: =IF('Preencher pelo celular'!D139="","",'Preencher pelo celular'!D139) | S26: =IF('Preencher pelo celular'!F139="","",'Preencher pelo celular'!F139) | T26: =IF(COUNT(B26,E26,H26,K26,N26,Q26)=0,"",AVERAGE(B26,E26,H26,K26,N26,Q26)) | U26: =IF(COUNT(D26,G26,J26,M26,P26,S26)=0,"",AVERAGE(D26,G26,J26,M26,P26,S26)) | V26: =IF(COUNT(C26,F26,I26,L26,O26,R26)=0,"",SUM(C26,F26,I26,L26,O26,R26))
A27: ='Preencher pelo celular'!A140 -> 46313 | B27: =IF('Preencher pelo celular'!C140="","",'Preencher pelo celular'!C140) | C27: =IF('Preencher pelo celular'!D140="","",'Preencher pelo celular'!D140) | D27: =IF('Preencher pelo celular'!F140="","",'Preencher pelo celular'!F140) | E27: =IF('Preencher pelo celular'!C141="","",'Preencher pelo celular'!C141) | F27: =IF('Preencher pelo celular'!D141="","",'Preencher pelo celular'!D141) | G27: =IF('Preencher pelo celular'!F141="","",'Preencher pelo celular'!F141) | H27: =IF('Preencher pelo celular'!C142="","",'Preencher pelo celular'!C142) | I27: =IF('Preencher pelo celular'!D142="","",'Preencher pelo celular'!D142) | J27: =IF('Preencher pelo celular'!F142="","",'Preencher pelo celular'!F142) | K27: =IF('Preencher pelo celular'!C143="","",'Preencher pelo celular'!C143) | L27: =IF('Preencher pelo celular'!D143="","",'Preencher pelo celular'!D143) | M27: =IF('Preencher pelo celular'!F143="","",'Preencher pelo celular'!F143) | N27: =IF('Preencher pelo celular'!C144="","",'Preencher pelo celular'!C144) | O27: =IF('Preencher pelo celular'!D144="","",'Preencher pelo celular'!D144) | P27: =IF('Preencher pelo celular'!F144="","",'Preencher pelo celular'!F144) | Q27: =IF('Preencher pelo celular'!C145="","",'Preencher pelo celular'!C145) | R27: =IF('Preencher pelo celular'!D145="","",'Preencher pelo celular'!D145) | S27: =IF('Preencher pelo celular'!F145="","",'Preencher pelo celular'!F145) | T27: =IF(COUNT(B27,E27,H27,K27,N27,Q27)=0,"",AVERAGE(B27,E27,H27,K27,N27,Q27)) | U27: =IF(COUNT(D27,G27,J27,M27,P27,S27)=0,"",AVERAGE(D27,G27,J27,M27,P27,S27)) | V27: =IF(COUNT(C27,F27,I27,L27,O27,R27)=0,"",SUM(C27,F27,I27,L27,O27,R27))
A28: ='Preencher pelo celular'!A146 -> 46314 | B28: =IF('Preencher pelo celular'!C146="","",'Preencher pelo celular'!C146) | C28: =IF('Preencher pelo celular'!D146="","",'Preencher pelo celular'!D146) | D28: =IF('Preencher pelo celular'!F146="","",'Preencher pelo celular'!F146) | E28: =IF('Preencher pelo celular'!C147="","",'Preencher pelo celular'!C147) | F28: =IF('Preencher pelo celular'!D147="","",'Preencher pelo celular'!D147) | G28: =IF('Preencher pelo celular'!F147="","",'Preencher pelo celular'!F147) | H28: =IF('Preencher pelo celular'!C148="","",'Preencher pelo celular'!C148) | I28: =IF('Preencher pelo celular'!D148="","",'Preencher pelo celular'!D148) | J28: =IF('Preencher pelo celular'!F148="","",'Preencher pelo celular'!F148) | K28: =IF('Preencher pelo celular'!C149="","",'Preencher pelo celular'!C149) | L28: =IF('Preencher pelo celular'!D149="","",'Preencher pelo celular'!D149) | M28: =IF('Preencher pelo celular'!F149="","",'Preencher pelo celular'!F149) | N28: =IF('Preencher pelo celular'!C150="","",'Preencher pelo celular'!C150) | O28: =IF('Preencher pelo celular'!D150="","",'Preencher pelo celular'!D150) | P28: =IF('Preencher pelo celular'!F150="","",'Preencher pelo celular'!F150) | Q28: =IF('Preencher pelo celular'!C151="","",'Preencher pelo celular'!C151) | R28: =IF('Preencher pelo celular'!D151="","",'Preencher pelo celular'!D151) | S28: =IF('Preencher pelo celular'!F151="","",'Preencher pelo celular'!F151) | T28: =IF(COUNT(B28,E28,H28,K28,N28,Q28)=0,"",AVERAGE(B28,E28,H28,K28,N28,Q28)) | U28: =IF(COUNT(D28,G28,J28,M28,P28,S28)=0,"",AVERAGE(D28,G28,J28,M28,P28,S28)) | V28: =IF(COUNT(C28,F28,I28,L28,O28,R28)=0,"",SUM(C28,F28,I28,L28,O28,R28))
A29: ='Preencher pelo celular'!A152 -> 46315 | B29: =IF('Preencher pelo celular'!C152="","",'Preencher pelo celular'!C152) | C29: =IF('Preencher pelo celular'!D152="","",'Preencher pelo celular'!D152) | D29: =IF('Preencher pelo celular'!F152="","",'Preencher pelo celular'!F152) | E29: =IF('Preencher pelo celular'!C153="","",'Preencher pelo celular'!C153) | F29: =IF('Preencher pelo celular'!D153="","",'Preencher pelo celular'!D153) | G29: =IF('Preencher pelo celular'!F153="","",'Preencher pelo celular'!F153) | H29: =IF('Preencher pelo celular'!C154="","",'Preencher pelo celular'!C154) | I29: =IF('Preencher pelo celular'!D154="","",'Preencher pelo celular'!D154) | J29: =IF('Preencher pelo celular'!F154="","",'Preencher pelo celular'!F154) | K29: =IF('Preencher pelo celular'!C155="","",'Preencher pelo celular'!C155) | L29: =IF('Preencher pelo celular'!D155="","",'Preencher pelo celular'!D155) | M29: =IF('Preencher pelo celular'!F155="","",'Preencher pelo celular'!F155) | N29: =IF('Preencher pelo celular'!C156="","",'Preencher pelo celular'!C156) | O29: =IF('Preencher pelo celular'!D156="","",'Preencher pelo celular'!D156) | P29: =IF('Preencher pelo celular'!F156="","",'Preencher pelo celular'!F156) | Q29: =IF('Preencher pelo celular'!C157="","",'Preencher pelo celular'!C157) | R29: =IF('Preencher pelo celular'!D157="","",'Preencher pelo celular'!D157) | S29: =IF('Preencher pelo celular'!F157="","",'Preencher pelo celular'!F157) | T29: =IF(COUNT(B29,E29,H29,K29,N29,Q29)=0,"",AVERAGE(B29,E29,H29,K29,N29,Q29)) | U29: =IF(COUNT(D29,G29,J29,M29,P29,S29)=0,"",AVERAGE(D29,G29,J29,M29,P29,S29)) | V29: =IF(COUNT(C29,F29,I29,L29,O29,R29)=0,"",SUM(C29,F29,I29,L29,O29,R29))
A30: ='Preencher pelo celular'!A158 -> 46316 | B30: =IF('Preencher pelo celular'!C158="","",'Preencher pelo celular'!C158) | C30: =IF('Preencher pelo celular'!D158="","",'Preencher pelo celular'!D158) | D30: =IF('Preencher pelo celular'!F158="","",'Preencher pelo celular'!F158) | E30: =IF('Preencher pelo celular'!C159="","",'Preencher pelo celular'!C159) | F30: =IF('Preencher pelo celular'!D159="","",'Preencher pelo celular'!D159) | G30: =IF('Preencher pelo celular'!F159="","",'Preencher pelo celular'!F159) | H30: =IF('Preencher pelo celular'!C160="","",'Preencher pelo celular'!C160) | I30: =IF('Preencher pelo celular'!D160="","",'Preencher pelo celular'!D160) | J30: =IF('Preencher pelo celular'!F160="","",'Preencher pelo celular'!F160) | K30: =IF('Preencher pelo celular'!C161="","",'Preencher pelo celular'!C161) | L30: =IF('Preencher pelo celular'!D161="","",'Preencher pelo celular'!D161) | M30: =IF('Preencher pelo celular'!F161="","",'Preencher pelo celular'!F161) | N30: =IF('Preencher pelo celular'!C162="","",'Preencher pelo celular'!C162) | O30: =IF('Preencher pelo celular'!D162="","",'Preencher pelo celular'!D162) | P30: =IF('Preencher pelo celular'!F162="","",'Preencher pelo celular'!F162) | Q30: =IF('Preencher pelo celular'!C163="","",'Preencher pelo celular'!C163) | R30: =IF('Preencher pelo celular'!D163="","",'Preencher pelo celular'!D163) | S30: =IF('Preencher pelo celular'!F163="","",'Preencher pelo celular'!F163) | T30: =IF(COUNT(B30,E30,H30,K30,N30,Q30)=0,"",AVERAGE(B30,E30,H30,K30,N30,Q30)) | U30: =IF(COUNT(D30,G30,J30,M30,P30,S30)=0,"",AVERAGE(D30,G30,J30,M30,P30,S30)) | V30: =IF(COUNT(C30,F30,I30,L30,O30,R30)=0,"",SUM(C30,F30,I30,L30,O30,R30))
A31: ='Preencher pelo celular'!A164 -> 46317 | B31: =IF('Preencher pelo celular'!C164="","",'Preencher pelo celular'!C164) | C31: =IF('Preencher pelo celular'!D164="","",'Preencher pelo celular'!D164) | D31: =IF('Preencher pelo celular'!F164="","",'Preencher pelo celular'!F164) | E31: =IF('Preencher pelo celular'!C165="","",'Preencher pelo celular'!C165) | F31: =IF('Preencher pelo celular'!D165="","",'Preencher pelo celular'!D165) | G31: =IF('Preencher pelo celular'!F165="","",'Preencher pelo celular'!F165) | H31: =IF('Preencher pelo celular'!C166="","",'Preencher pelo celular'!C166) | I31: =IF('Preencher pelo celular'!D166="","",'Preencher pelo celular'!D166) | J31: =IF('Preencher pelo celular'!F166="","",'Preencher pelo celular'!F166) | K31: =IF('Preencher pelo celular'!C167="","",'Preencher pelo celular'!C167) | L31: =IF('Preencher pelo celular'!D167="","",'Preencher pelo celular'!D167) | M31: =IF('Preencher pelo celular'!F167="","",'Preencher pelo celular'!F167) | N31: =IF('Preencher pelo celular'!C168="","",'Preencher pelo celular'!C168) | O31: =IF('Preencher pelo celular'!D168="","",'Preencher pelo celular'!D168) | P31: =IF('Preencher pelo celular'!F168="","",'Preencher pelo celular'!F168) | Q31: =IF('Preencher pelo celular'!C169="","",'Preencher pelo celular'!C169) | R31: =IF('Preencher pelo celular'!D169="","",'Preencher pelo celular'!D169) | S31: =IF('Preencher pelo celular'!F169="","",'Preencher pelo celular'!F169) | T31: =IF(COUNT(B31,E31,H31,K31,N31,Q31)=0,"",AVERAGE(B31,E31,H31,K31,N31,Q31)) | U31: =IF(COUNT(D31,G31,J31,M31,P31,S31)=0,"",AVERAGE(D31,G31,J31,M31,P31,S31)) | V31: =IF(COUNT(C31,F31,I31,L31,O31,R31)=0,"",SUM(C31,F31,I31,L31,O31,R31))
A32: ='Preencher pelo celular'!A170 -> 46318 | B32: =IF('Preencher pelo celular'!C170="","",'Preencher pelo celular'!C170) | C32: =IF('Preencher pelo celular'!D170="","",'Preencher pelo celular'!D170) | D32: =IF('Preencher pelo celular'!F170="","",'Preencher pelo celular'!F170) | E32: =IF('Preencher pelo celular'!C171="","",'Preencher pelo celular'!C171) | F32: =IF('Preencher pelo celular'!D171="","",'Preencher pelo celular'!D171) | G32: =IF('Preencher pelo celular'!F171="","",'Preencher pelo celular'!F171) | H32: =IF('Preencher pelo celular'!C172="","",'Preencher pelo celular'!C172) | I32: =IF('Preencher pelo celular'!D172="","",'Preencher pelo celular'!D172) | J32: =IF('Preencher pelo celular'!F172="","",'Preencher pelo celular'!F172) | K32: =IF('Preencher pelo celular'!C173="","",'Preencher pelo celular'!C173) | L32: =IF('Preencher pelo celular'!D173="","",'Preencher pelo celular'!D173) | M32: =IF('Preencher pelo celular'!F173="","",'Preencher pelo celular'!F173) | N32: =IF('Preencher pelo celular'!C174="","",'Preencher pelo celular'!C174) | O32: =IF('Preencher pelo celular'!D174="","",'Preencher pelo celular'!D174) | P32: =IF('Preencher pelo celular'!F174="","",'Preencher pelo celular'!F174) | Q32: =IF('Preencher pelo celular'!C175="","",'Preencher pelo celular'!C175) | R32: =IF('Preencher pelo celular'!D175="","",'Preencher pelo celular'!D175) | S32: =IF('Preencher pelo celular'!F175="","",'Preencher pelo celular'!F175) | T32: =IF(COUNT(B32,E32,H32,K32,N32,Q32)=0,"",AVERAGE(B32,E32,H32,K32,N32,Q32)) | U32: =IF(COUNT(D32,G32,J32,M32,P32,S32)=0,"",AVERAGE(D32,G32,J32,M32,P32,S32)) | V32: =IF(COUNT(C32,F32,I32,L32,O32,R32)=0,"",SUM(C32,F32,I32,L32,O32,R32))
A33: ='Preencher pelo celular'!A176 -> 46319 | B33: =IF('Preencher pelo celular'!C176="","",'Preencher pelo celular'!C176) | C33: =IF('Preencher pelo celular'!D176="","",'Preencher pelo celular'!D176) | D33: =IF('Preencher pelo celular'!F176="","",'Preencher pelo celular'!F176) | E33: =IF('Preencher pelo celular'!C177="","",'Preencher pelo celular'!C177) | F33: =IF('Preencher pelo celular'!D177="","",'Preencher pelo celular'!D177) | G33: =IF('Preencher pelo celular'!F177="","",'Preencher pelo celular'!F177) | H33: =IF('Preencher pelo celular'!C178="","",'Preencher pelo celular'!C178) | I33: =IF('Preencher pelo celular'!D178="","",'Preencher pelo celular'!D178) | J33: =IF('Preencher pelo celular'!F178="","",'Preencher pelo celular'!F178) | K33: =IF('Preencher pelo celular'!C179="","",'Preencher pelo celular'!C179) | L33: =IF('Preencher pelo celular'!D179="","",'Preencher pelo celular'!D179) | M33: =IF('Preencher pelo celular'!F179="","",'Preencher pelo celular'!F179) | N33: =IF('Preencher pelo celular'!C180="","",'Preencher pelo celular'!C180) | O33: =IF('Preencher pelo celular'!D180="","",'Preencher pelo celular'!D180) | P33: =IF('Preencher pelo celular'!F180="","",'Preencher pelo celular'!F180) | Q33: =IF('Preencher pelo celular'!C181="","",'Preencher pelo celular'!C181) | R33: =IF('Preencher pelo celular'!D181="","",'Preencher pelo celular'!D181) | S33: =IF('Preencher pelo celular'!F181="","",'Preencher pelo celular'!F181) | T33: =IF(COUNT(B33,E33,H33,K33,N33,Q33)=0,"",AVERAGE(B33,E33,H33,K33,N33,Q33)) | U33: =IF(COUNT(D33,G33,J33,M33,P33,S33)=0,"",AVERAGE(D33,G33,J33,M33,P33,S33)) | V33: =IF(COUNT(C33,F33,I33,L33,O33,R33)=0,"",SUM(C33,F33,I33,L33,O33,R33))
A34: ='Preencher pelo celular'!A182 -> 46320 | B34: =IF('Preencher pelo celular'!C182="","",'Preencher pelo celular'!C182) | C34: =IF('Preencher pelo celular'!D182="","",'Preencher pelo celular'!D182) | D34: =IF('Preencher pelo celular'!F182="","",'Preencher pelo celular'!F182) | E34: =IF('Preencher pelo celular'!C183="","",'Preencher pelo celular'!C183) | F34: =IF('Preencher pelo celular'!D183="","",'Preencher pelo celular'!D183) | G34: =IF('Preencher pelo celular'!F183="","",'Preencher pelo celular'!F183) | H34: =IF('Preencher pelo celular'!C184="","",'Preencher pelo celular'!C184) | I34: =IF('Preencher pelo celular'!D184="","",'Preencher pelo celular'!D184) | J34: =IF('Preencher pelo celular'!F184="","",'Preencher pelo celular'!F184) | K34: =IF('Preencher pelo celular'!C185="","",'Preencher pelo celular'!C185) | L34: =IF('Preencher pelo celular'!D185="","",'Preencher pelo celular'!D185) | M34: =IF('Preencher pelo celular'!F185="","",'Preencher pelo celular'!F185) | N34: =IF('Preencher pelo celular'!C186="","",'Preencher pelo celular'!C186) | O34: =IF('Preencher pelo celular'!D186="","",'Preencher pelo celular'!D186) | P34: =IF('Preencher pelo celular'!F186="","",'Preencher pelo celular'!F186) | Q34: =IF('Preencher pelo celular'!C187="","",'Preencher pelo celular'!C187) | R34: =IF('Preencher pelo celular'!D187="","",'Preencher pelo celular'!D187) | S34: =IF('Preencher pelo celular'!F187="","",'Preencher pelo celular'!F187) | T34: =IF(COUNT(B34,E34,H34,K34,N34,Q34)=0,"",AVERAGE(B34,E34,H34,K34,N34,Q34)) | U34: =IF(COUNT(D34,G34,J34,M34,P34,S34)=0,"",AVERAGE(D34,G34,J34,M34,P34,S34)) | V34: =IF(COUNT(C34,F34,I34,L34,O34,R34)=0,"",SUM(C34,F34,I34,L34,O34,R34))
A35: ='Preencher pelo celular'!A188 -> 46321 | B35: =IF('Preencher pelo celular'!C188="","",'Preencher pelo celular'!C188) | C35: =IF('Preencher pelo celular'!D188="","",'Preencher pelo celular'!D188) | D35: =IF('Preencher pelo celular'!F188="","",'Preencher pelo celular'!F188) | E35: =IF('Preencher pelo celular'!C189="","",'Preencher pelo celular'!C189) | F35: =IF('Preencher pelo celular'!D189="","",'Preencher pelo celular'!D189) | G35: =IF('Preencher pelo celular'!F189="","",'Preencher pelo celular'!F189) | H35: =IF('Preencher pelo celular'!C190="","",'Preencher pelo celular'!C190) | I35: =IF('Preencher pelo celular'!D190="","",'Preencher pelo celular'!D190) | J35: =IF('Preencher pelo celular'!F190="","",'Preencher pelo celular'!F190) | K35: =IF('Preencher pelo celular'!C191="","",'Preencher pelo celular'!C191) | L35: =IF('Preencher pelo celular'!D191="","",'Preencher pelo celular'!D191) | M35: =IF('Preencher pelo celular'!F191="","",'Preencher pelo celular'!F191) | N35: =IF('Preencher pelo celular'!C192="","",'Preencher pelo celular'!C192) | O35: =IF('Preencher pelo celular'!D192="","",'Preencher pelo celular'!D192) | P35: =IF('Preencher pelo celular'!F192="","",'Preencher pelo celular'!F192) | Q35: =IF('Preencher pelo celular'!C193="","",'Preencher pelo celular'!C193) | R35: =IF('Preencher pelo celular'!D193="","",'Preencher pelo celular'!D193) | S35: =IF('Preencher pelo celular'!F193="","",'Preencher pelo celular'!F193) | T35: =IF(COUNT(B35,E35,H35,K35,N35,Q35)=0,"",AVERAGE(B35,E35,H35,K35,N35,Q35)) | U35: =IF(COUNT(D35,G35,J35,M35,P35,S35)=0,"",AVERAGE(D35,G35,J35,M35,P35,S35)) | V35: =IF(COUNT(C35,F35,I35,L35,O35,R35)=0,"",SUM(C35,F35,I35,L35,O35,R35))
A36: ='Preencher pelo celular'!A194 -> 46322 | B36: =IF('Preencher pelo celular'!C194="","",'Preencher pelo celular'!C194) | C36: =IF('Preencher pelo celular'!D194="","",'Preencher pelo celular'!D194) | D36: =IF('Preencher pelo celular'!F194="","",'Preencher pelo celular'!F194) | E36: =IF('Preencher pelo celular'!C195="","",'Preencher pelo celular'!C195) | F36: =IF('Preencher pelo celular'!D195="","",'Preencher pelo celular'!D195) | G36: =IF('Preencher pelo celular'!F195="","",'Preencher pelo celular'!F195) | H36: =IF('Preencher pelo celular'!C196="","",'Preencher pelo celular'!C196) | I36: =IF('Preencher pelo celular'!D196="","",'Preencher pelo celular'!D196) | J36: =IF('Preencher pelo celular'!F196="","",'Preencher pelo celular'!F196) | K36: =IF('Preencher pelo celular'!C197="","",'Preencher pelo celular'!C197) | L36: =IF('Preencher pelo celular'!D197="","",'Preencher pelo celular'!D197) | M36: =IF('Preencher pelo celular'!F197="","",'Preencher pelo celular'!F197) | N36: =IF('Preencher pelo celular'!C198="","",'Preencher pelo celular'!C198) | O36: =IF('Preencher pelo celular'!D198="","",'Preencher pelo celular'!D198) | P36: =IF('Preencher pelo celular'!F198="","",'Preencher pelo celular'!F198) | Q36: =IF('Preencher pelo celular'!C199="","",'Preencher pelo celular'!C199) | R36: =IF('Preencher pelo celular'!D199="","",'Preencher pelo celular'!D199) | S36: =IF('Preencher pelo celular'!F199="","",'Preencher pelo celular'!F199) | T36: =IF(COUNT(B36,E36,H36,K36,N36,Q36)=0,"",AVERAGE(B36,E36,H36,K36,N36,Q36)) | U36: =IF(COUNT(D36,G36,J36,M36,P36,S36)=0,"",AVERAGE(D36,G36,J36,M36,P36,S36)) | V36: =IF(COUNT(C36,F36,I36,L36,O36,R36)=0,"",SUM(C36,F36,I36,L36,O36,R36))
A37: ='Preencher pelo celular'!A200 -> 46323 | B37: =IF('Preencher pelo celular'!C200="","",'Preencher pelo celular'!C200) | C37: =IF('Preencher pelo celular'!D200="","",'Preencher pelo celular'!D200) | D37: =IF('Preencher pelo celular'!F200="","",'Preencher pelo celular'!F200) | E37: =IF('Preencher pelo celular'!C201="","",'Preencher pelo celular'!C201) | F37: =IF('Preencher pelo celular'!D201="","",'Preencher pelo celular'!D201) | G37: =IF('Preencher pelo celular'!F201="","",'Preencher pelo celular'!F201) | H37: =IF('Preencher pelo celular'!C202="","",'Preencher pelo celular'!C202) | I37: =IF('Preencher pelo celular'!D202="","",'Preencher pelo celular'!D202) | J37: =IF('Preencher pelo celular'!F202="","",'Preencher pelo celular'!F202) | K37: =IF('Preencher pelo celular'!C203="","",'Preencher pelo celular'!C203) | L37: =IF('Preencher pelo celular'!D203="","",'Preencher pelo celular'!D203) | M37: =IF('Preencher pelo celular'!F203="","",'Preencher pelo celular'!F203) | N37: =IF('Preencher pelo celular'!C204="","",'Preencher pelo celular'!C204) | O37: =IF('Preencher pelo celular'!D204="","",'Preencher pelo celular'!D204) | P37: =IF('Preencher pelo celular'!F204="","",'Preencher pelo celular'!F204) | Q37: =IF('Preencher pelo celular'!C205="","",'Preencher pelo celular'!C205) | R37: =IF('Preencher pelo celular'!D205="","",'Preencher pelo celular'!D205) | S37: =IF('Preencher pelo celular'!F205="","",'Preencher pelo celular'!F205) | T37: =IF(COUNT(B37,E37,H37,K37,N37,Q37)=0,"",AVERAGE(B37,E37,H37,K37,N37,Q37)) | U37: =IF(COUNT(D37,G37,J37,M37,P37,S37)=0,"",AVERAGE(D37,G37,J37,M37,P37,S37)) | V37: =IF(COUNT(C37,F37,I37,L37,O37,R37)=0,"",SUM(C37,F37,I37,L37,O37,R37))
A38: ='Preencher pelo celular'!A206 -> 46324 | B38: =IF('Preencher pelo celular'!C206="","",'Preencher pelo celular'!C206) | C38: =IF('Preencher pelo celular'!D206="","",'Preencher pelo celular'!D206) | D38: =IF('Preencher pelo celular'!F206="","",'Preencher pelo celular'!F206) | E38: =IF('Preencher pelo celular'!C207="","",'Preencher pelo celular'!C207) | F38: =IF('Preencher pelo celular'!D207="","",'Preencher pelo celular'!D207) | G38: =IF('Preencher pelo celular'!F207="","",'Preencher pelo celular'!F207) | H38: =IF('Preencher pelo celular'!C208="","",'Preencher pelo celular'!C208) | I38: =IF('Preencher pelo celular'!D208="","",'Preencher pelo celular'!D208) | J38: =IF('Preencher pelo celular'!F208="","",'Preencher pelo celular'!F208) | K38: =IF('Preencher pelo celular'!C209="","",'Preencher pelo celular'!C209) | L38: =IF('Preencher pelo celular'!D209="","",'Preencher pelo celular'!D209) | M38: =IF('Preencher pelo celular'!F209="","",'Preencher pelo celular'!F209) | N38: =IF('Preencher pelo celular'!C210="","",'Preencher pelo celular'!C210) | O38: =IF('Preencher pelo celular'!D210="","",'Preencher pelo celular'!D210) | P38: =IF('Preencher pelo celular'!F210="","",'Preencher pelo celular'!F210) | Q38: =IF('Preencher pelo celular'!C211="","",'Preencher pelo celular'!C211) | R38: =IF('Preencher pelo celular'!D211="","",'Preencher pelo celular'!D211) | S38: =IF('Preencher pelo celular'!F211="","",'Preencher pelo celular'!F211) | T38: =IF(COUNT(B38,E38,H38,K38,N38,Q38)=0,"",AVERAGE(B38,E38,H38,K38,N38,Q38)) | U38: =IF(COUNT(D38,G38,J38,M38,P38,S38)=0,"",AVERAGE(D38,G38,J38,M38,P38,S38)) | V38: =IF(COUNT(C38,F38,I38,L38,O38,R38)=0,"",SUM(C38,F38,I38,L38,O38,R38))
